<mujoco model="diffbot_planar">
  <!--
    AUTO-GENERATED from diffbot.urdf by urdf_to_mjcf_planar.py — do not hand-edit;
    re-run the script. Planar free-plane joints + velocity servos are MineWorld
    POC control (same contract as box_mech / planar_cart).
  -->
  <option timestep="0.002" integrator="RK4" gravity="0 0 -9.81"/>

  <default>
    <geom contype="1" conaffinity="1" friction="0.8 0.02 0.01"/>
  </default>

  <worldbody>
    <body name="chassis" pos="0 0 0.5">
      <joint name="slide_x" type="slide" axis="1 0 0" damping="0.2"/>
      <joint name="slide_y" type="slide" axis="0 1 0" damping="0.2"/>
      <joint name="yaw_z" type="hinge" axis="0 0 1" damping="0.05"/>
      <inertial pos="0 0 0" mass="12.0" diaginertia="0.15 0.25 0.3"/>
      <geom name="chassis_box" type="box" size="0.5 0.5 0.25"
            rgba="1.0 0.4235294118 0.03921568627 1"/>
      <geom name="left_wheel" type="cylinder" size="0.15 0.1" pos="0.0 -0.5 -0.25" quat="0.7071 0.7071 0 0" mass="0" contype="0" conaffinity="0" rgba="0 0 0 1"/>
      <geom name="right_wheel" type="cylinder" size="0.15 0.1" pos="0.0 0.5 -0.25" quat="0.7071 0.7071 0 0" mass="0" contype="0" conaffinity="0" rgba="0 0 0 1"/>
      <geom name="caster_frontal_wheel" type="sphere" size="0.15" pos="0.35 0.0 -0.25" mass="0" contype="0" conaffinity="0" rgba="1 1 1 1"/>
      <geom name="caster_rear_wheel" type="sphere" size="0.15" pos="-0.35 0.0 -0.25" mass="0" contype="0" conaffinity="0" rgba="1 1 1 1"/>
    </body>
  </worldbody>

  <actuator>
    <velocity name="vx" joint="slide_x" kv="120" forcerange="-400 400" ctrlrange="-3 3"/>
    <velocity name="vy" joint="slide_y" kv="120" forcerange="-400 400" ctrlrange="-3 3"/>
    <velocity name="yaw_rate" joint="yaw_z" kv="60" forcerange="-200 200" ctrlrange="-6 6"/>
  </actuator>
</mujoco>
