<mujoco model="diffbot_race">
  <!--
    Race chassis: planar DiffBot with motor (force/torque) actuators so
    mass+damping give throttle acceleration (demo_race). Wheels F6 kinematic.
  -->
  <option timestep="0.002" integrator="RK4" gravity="0 0 -9.81"/>

  <default>
    <geom contype="1" conaffinity="1" friction="0.8 0.02 0.01"/>
  </default>

  <worldbody>
    <body name="chassis" pos="0 0 0.5">
      <!-- Damping ≈ terminal ~15 m/s at full throttle (F≈850 → v=F/d). -->
      <joint name="slide_x" type="slide" axis="1 0 0" damping="55"/>
      <joint name="slide_y" type="slide" axis="0 1 0" damping="70"/>
      <joint name="yaw_z" type="hinge" axis="0 0 1" damping="12"/>
      <inertial pos="0 0 0" mass="24.0" diaginertia="0.35 0.55 0.7"/>
      <geom name="chassis_box" type="box" size="0.5 0.5 0.25"
            rgba="0.15 0.55 0.95 1"/>
      <geom name="caster_frontal_wheel" type="sphere" size="0.15" pos="0.35 0.0 -0.25" mass="0" contype="0" conaffinity="0" rgba="1 1 1 1"/>
      <geom name="caster_rear_wheel" type="sphere" size="0.15" pos="-0.35 0.0 -0.25" mass="0" contype="0" conaffinity="0" rgba="1 1 1 1"/>
      <body name="left_wheel" pos="0.0 -0.5 -0.25">
        <joint name="left_wheel_joint" type="hinge" axis="0 1 0" damping="0.01"/>
        <geom name="left_wheel_geom" type="cylinder" size="0.15 0.1" quat="0.7071 0.7071 0 0" mass="0.05" contype="0" conaffinity="0" rgba="0 0 0 1"/>
      </body>
      <body name="right_wheel" pos="0.0 0.5 -0.25">
        <joint name="right_wheel_joint" type="hinge" axis="0 1 0" damping="0.01"/>
        <geom name="right_wheel_geom" type="cylinder" size="0.15 0.1" quat="0.7071 0.7071 0 0" mass="0.05" contype="0" conaffinity="0" rgba="0 0 0 1"/>
      </body>
    </body>
  </worldbody>

  <actuator>
    <!-- ctrl ∈ [-1,1] = throttle / strafe / steer; gear → Newtons / N·m. -->
    <motor name="vx" joint="slide_x" gear="850" ctrlrange="-1 1"/>
    <motor name="vy" joint="slide_y" gear="320" ctrlrange="-1 1"/>
    <motor name="yaw_rate" joint="yaw_z" gear="160" ctrlrange="-1 1"/>
  </actuator>
</mujoco>
